Workbook
Name SegmentaçãodeDados_ANO: #N/A
Name SegmentaçãodeDados_LOCALIDADE_MACRO2: #N/A

Sheet Quadro
A1: JFA
A2: HL5-D | B2: ATIVIDADE | C2: STATUS | D2: CONCLUÍDO | E2: FEVEREIRO | J2: MARÇO | O2: ABRIL | Q2: TOTAL | T2: IDMETRO | U2: UFSIGLA | V2: TIPO | W2: PRED | X2: REG | Y2: ESCOPO | Z2: PER | AA2: FLAG | AB2: PROJETO_ESP | AC2: EAP_METRO
E3: 45712 | F3: 45713 | G3: 45714 | H3: 45715 | I3: 45716 | J3: W10 | K3: W11 | L3: W12 | M3: W13 | N3: W14 | O3: W15 | P3: W16 | T3: M2024EST_MGUNM_01 | U3: MGUNM | V3: HL5-D | X3: MG | Y3: MARÇO_25_COMPROMISSO | Z3: MAR | AA3: SINC | AB3: 5G_500K - | AC3: CONSTRUÇÃO/FORMATACAO
B4: CONSTRUÇÃO REDE | C4: P | D4: 0 | K4: 3 | Q4: =SUM(E4:P4) -> 3 | T4: M2024_MGRMM_01 | U4: MGRMM | V4: HL5-G | W4: MGBHN | X4: MG | Y4: MARÇO_25_ANT_ABR | Z4: 0 | AA4: NÃO | AB4: 5G_200K - | AC4: CONSTRUÇÃO/FORMATACAO
C5: R | D5: 0 | Q5: =SUM(E5:P5) -> 0 | T5: M2024EST_MGUAV_01 | U5: MGUAV | V5: HL5-G | W5: MGUNM | X5: MG | Y5: MARÇO_25_COMPROMISSO | Z5: MAR | AA5: SINC | AB5: 5G_500K - | AC5: CONSTRUÇÃO/FORMATACAO
T6: M2025_MGNPG_01 | U6: MGNPG | V6: HL5-G | W6: MGNRD | X6: MG | Y6: MARÇO_25_ANT_ABR | Z6: 0 | AA6: NÃO | AB6: 5G_100K - | AC6: VALIDACAO LIB.IMPLANTAÇÃO
B7: ATIVAÇÃO | C7: P | D7: 0 | G7: 1 | K7: 2 | L7: 3 | Q7: =SUM(E7:P7) -> 6 | T7: M2023_MGSLW_01 | U7: MGSLW | V7: 0 | X7: MG | Y7: MARÇO_25_ANT_ABR | Z7: 0 | AA7: NÃO | AB7: 5G_200K - | AC7: CONSTRUÇÃO/FORMATACAO
C8: R | D8: 0 | Q8: =SUM(E8:P8) -> 0 | T8: M2025_MGDBE_01 | U8: MGDBE | V8: HL5-G | X8: MG | Y8: MARÇO_25_ANT_ABR | AA8: NÃO | AB8: N/A | AC8: VALIDACAO LIB.IMPLANTAÇÃO
T9: M2024SMALL_MGCR2_01 | U9: MGCR2 | V9: SmallCell | X9: MG | Y9: MARÇO_25_COMPROMISSO | Z9: MAR | AA9: SINC | AB9: 5G_500K - | AC9: VALIDACAO LIB.IMPLANTAÇÃO
T10: M2024SMALL_MGUC1_01 | U10: MGUC1 | V10: SmallCell | X10: MG | Y10: MARÇO_25_COMPROMISSO | Z10: MAR | AA10: SINC | AB10: 5G_500K - | AC10: VALIDACAO LIB.IMPLANTAÇÃO
A11: JFA | T11: M2024SMALL_MGUC2_01 | U11: MGUC2 | V11: SmallCell | X11: MG | Y11: MARÇO_25_ANT_ABR | Z11: 0 | AA11: NÃO | AB11: 5G_500K - | AC11: PROJETO METRO
A12: HL5-G | B12: ATIVIDADE | C12: STATUS | D12: CONCLUÍDO | E12: FEVEREIRO | J12: MARÇO | O12: ABRIL | Q12: TOTAL | T12: M2024SMALL_MGUC3_01 | U12: MGUC3 | V12: SmallCell | X12: MG | Y12: MARÇO_25_ANT_ABR | Z12: 0 | AA12: NÃO | AB12: 5G_500K - | AC12: VALIDACAO LIB.IMPLANTAÇÃO
E13: 45712 | F13: 45713 | G13: 45714 | H13: 45715 | I13: 45716 | J13: W10 | K13: W11 | L13: W12 | M13: W13 | N13: W14 | O13: W15 | P13: W16 | T13: M2023_MGDSJ_01 | U13: MGDSJ | V13: HL5-D | X13: MG | Y13: MARÇO_25_ANT_ABR | Z13: 0 | AA13: NÃO | AB13: CONCESSÃO_CAPACIDADE - 5G_200K - | AC13: VALIDACAO LIB.IMPLANTAÇÃO
B14: CONSTRUÇÃO REDE | C14: P | D14: 68 | I14: 1 | J14: 2 | K14: 2 | L14: 1 | M14: 6 | N14: 4 | O14: 6 | P14: 5 | Q14: =SUM(E14:P14) -> 27 | T14: M2024EST_MGSCZ_01 | U14: MGSCZ | V14: HL5-G | W14: MGCIN | X14: MG | Y14: MARÇO_25_ANT_ABR | Z14: 0 | AA14: NÃO | AB14: 5G_500K - | AC14: CONSTRUÇÃO/FORMATACAO
C15: R | D15: =D14-Q14 -> 41 | Q15: =SUM(E15:P15) -> 0 | T15: M2024EST_MGUMS_01 | U15: MGUMS | V15: HL5-D | X15: MG | Y15: MARÇO_25_COMPROMISSO | Z15: 0 | AA15: NÃO | AB15: 5G_500K - | AC15: CONSTRUÇÃO/FORMATACAO
T16: M2024EST_MGUPR_01 | U16: MGUPR | V16: HL5-G | W16: MGUMS | X16: MG | Y16: MARÇO_25_COMPROMISSO | Z16: 0 | AA16: NÃO | AB16: 5G_500K - | AC16: VALIDACAO DRAFT
B17: ATIVAÇÃO | C17: P | D17: 68 | E17: 1 | F17: 1 | G17: 2 | H17: 2 | I17: 3 | J17: 3 | K17: 2 | L17: 3 | M17: 3 | N17: 10 | O17: 13 | P17: 11 | Q17: =SUM(E17:P17) -> 54 | T17: M2024EST_MGURS_01 | U17: MGURS | V17: HL5-G | X17: MG | Y17: MARÇO_25_COMPROMISSO | Z17: 0 | AA17: NÃO | AB17: 5G_500K - | AC17: CONSTRUÇÃO/FORMATACAO
C18: R | D18: =D17-Q17 -> 14 | Q18: =SUM(E18:P18) -> 0 | T18: M2024_MGUC4_01 | U18: MGUC4 | V18: SmallCell | X18: MG | Y18: MARÇO_25_COMPROMISSO | Z18: MAR | AA18: SINC | AB18: 5G_500K - | AC18: CONSTRUÇÃO/FORMATACAO
T19: M2025_MGJBI_01 | U19: MGJBI | V19: HL5-G | W19: MGAPD | X19: MG | Y19: MARÇO_25_ANT_ABR | Z19: 0 | AA19: NÃO | AB19: 5G_500K - | AC19: CONSTRUÇÃO/FORMATACAO
T20: M2024EST_MGTCN_01 | U20: MGTCN | V20: HL5-G | X20: MG | Y20: MARÇO_25_ANT_ABR | Z20: 0 | AA20: NÃO | AB20: 5G_500K - | AC20: CONSTRUÇÃO/FORMATACAO
T21: M2024EST_MGUMN_01 | U21: MGUMN | V21: HL5-G | W21: MGUMS | X21: MG | Y21: MARÇO_25_ANT_ABR | Z21: 0 | AA21: NÃO | AB21: 5G_500K - | AC21: VALIDACAO DRAFT
T22: M2023_MGGCU_01 | U22: MGGCU | V22: 0 | X22: MG | Y22: MARÇO_25_COMPROMISSO | Z22: MAR | AA22: SINC | AB22: 5G_500K - | AC22: VALIDACAO DRAFT
T23: M2025_MGJJO_01 | U23: MGJJO | V23: HL5-G | X23: MG | Y23: MARÇO_25_ANT_ABR | Z23: 0 | AA23: NÃO | AB23: 5G_500K - | AC23: VALIDACAO DRAFT
A24: ULA | B24: ATIVIDADE | C24: STATUS | D24: CONCLUÍDO | E24: FEVEREIRO | J24: MARÇO | O24: ABRIL | Q24: TOTAL | T24: M2024_MGSLZ_01 | U24: MGSLZ | V24: HL5-G | W24: MGJSO | X24: MG | Y24: MARÇO_25_ANT_ABR | Z24: ABR | AA24: NÃO | AB24: N/A | AC24: VALIDACAO DRAFT
A25: HL4 | E25: 45712 | F25: 45713 | G25: 45714 | H25: 45715 | I25: 45716 | J25: W10 | K25: W11 | L25: W12 | M25: W13 | N25: W14 | O25: W15 | P25: W16 | T25: M2024_MGKML_01 | U25: MGKML | V25: HL5-G | W25: MGCBP | X25: MG | Y25: MARÇO_25_ANT_ABR | Z25: 0 | AA25: NÃO | AB25: TAV - | AC25: VALIDACAO DRAFT
B26: CONSTRUÇÃO REDE | C26: P | D26: 4 | J26: 1 | K26: 1 | L26: 1 | Q26: =SUM(E26:P26) -> 3 | T26: M2024_MGSNE_01 | U26: MGSNE | V26: HL5-G | X26: MG | Y26: MARÇO_25_ANT_ABR | Z26: ABR | AA26: NÃO | AB26: N/A | AC26: VALIDACAO DRAFT
C27: R | D27: 1 | Q27: =SUM(E27:P27) -> 0 | T27: M2024_MGNVM_01 | U27: MGNVM | V27: HL5-G | W27: MGNLA | X27: MG | Y27: MARÇO_25_ANT_ABR | Z27: 0 | AA27: NÃO | AB27: N/A | AC27: VALIDACAO DRAFT
T28: M2025_MGJZM_01 | U28: MGJZM | V28: HL5-G | W28: MGSDE | X28: MG | Y28: MARÇO_25_COMPROMISSO | Z28: 0 | AA28: SINC | AB28: N/A | AC28: VALIDACAO DRAFT
B29: ATIVAÇÃO | C29: P | D29: =D26 -> 4 | K29: 1 | L29: 1 | M29: 1 | Q29: =SUM(E29:P29) -> 3 | T29: M2025_MGJJJA_01 | U29: MGJJJ | V29: HL5-G | X29: MG | Y29: MARÇO_25_ANT_ABR | Z29: 0 | AA29: NÃO | AB29: 5G_500K - | AC29: VALIDACAO DRAFT
C30: R | D30: =D29-Q29 -> 1 | Q30: =SUM(E30:P30) -> 0 | T30: M2025_MGCBP_01 | U30: MGCBP | V30: HL5-D | X30: MG | Y30: MARÇO_25_ANT_ABR | Z30: 0 | AA30: NÃO | AB30: TAV - | AC30: VALIDACAO DRAFT
T31: M2025_MGSNG_01 | U31: MGSNG | V31: HL5-G | W31: MGSGT | X31: MG | Y31: MARÇO_25_ANT_ABR | Z31: 0 | AA31: NÃO | AB31: N/A | AC31: VALIDACAO LIB.IMPLANTAÇÃO
W32: 45745 | X32: W13
W33: 45746 | X33: W14
A34: ULA | B34: ATIVIDADE | C34: STATUS | D34: CONCLUÍDO | E34: FEVEREIRO | J34: MARÇO | O34: ABRIL | Q34: TOTAL | W34: 45747 | X34: W14
A35: HL5-D | E35: 45712 | F35: 45713 | G35: 45714 | H35: 45715 | I35: 45716 | J35: W10 | K35: W11 | L35: W12 | M35: W13 | N35: W14 | O35: W15 | P35: W16 | W35: 45748 | X35: W14
B36: CONSTRUÇÃO REDE | C36: P | D36: 18 | F36: 1 | I36: 1 | J36: 2 | K36: 1 | L36: 1 | M36: 3 | Q36: =SUM(E36:P36) -> 9 | W36: 45749 | X36: W14
C37: R | D37: =D36-Q36 -> 9 | Q37: =SUM(E37:P37) -> 0 | W37: 45750 | X37: W14
W38: 45751 | X38: W14
B39: ATIVAÇÃO | C39: P | D39: =D36 -> 18 | E39: 1 | F39: 1 | G39: 2 | K39: 3 | L39: 2 | M39: 3 | N39: 1 | Q39: =SUM(E39:P39) -> 13 | W39: 45752 | X39: W14
C40: R | D40: =D39-Q39 -> 5 | Q40: =SUM(E40:P40) -> 0 | W40: 45753 | X40: W15
...

Sheet PPT_
R1: UBERABA | Z1: GOV. VALADARES | AH1: SETE LAGOAS | AP1: UBERLANDIA
P2: b
R3: ELEMENTO | S3: MIGRADO | T3: PENDENTE | U3: PENDENTE | V3: TOTAL | W3: Rádio | X3: Projetos | Z3: ELEMENTO | AA3: MIGRADO | AB3: PENDENTE | AC3: PENDENTE | AD3: TOTAL | AE3: Rádio | AF3: Projetos | AH3: ELEMENTO | AI3: MIGRADO | AJ3: PENDENTE | AK3: PENDENTE | AL3: TOTAL | AM3: Rádio | AN3: Projetos | AP3: ELEMENTO | AQ3: MIGRADO | AR3: PENDENTE | AS3: PENDENTE | AT3: TOTAL | AU3: Rádio | AV3: Projetos
S4: FUSION | T4: CONSTRUÇÃO | U4: ATIVAÇÃO | V4: SITES | AA4: FUSION | AB4: CONSTRUÇÃO | AC4: ATIVAÇÃO | AD4: SITES | AI4: FUSION | AJ4: CONSTRUÇÃO | AK4: ATIVAÇÃO | AL4: SITES | AQ4: FUSION | AR4: CONSTRUÇÃO | AS4: ATIVAÇÃO | AT4: SITES
R5: HL4 | S5: 1 | U5: 1 | V5: =S5+U5+W5 -> 2 | W5: 0 | X5: 0 | Z5: HL4 | AA5: 2 | AD5: =AA5+AC5+AE5 -> 2 | AE5: 0 | AF5: 0 | AH5: HL4 | AI5: 1 | AL5: =AI5+AK5+AM5 -> 1 | AM5: 0 | AN5: 0 | AP5: HL4 | AQ5: 1 | AR5: 3 | AS5: 3 | AT5: =AQ5+AS5+AU5 -> 4 | AU5: 0 | AV5: 0
R6: HL5-D | S6: 2 | T6: 3 | U6: 5 | V6: =S6+U6+W6 -> 8 | W6: 1 | X6: 0 | Z6: HL5-D | AB6: 1 | AC6: 4 | AD6: =AA6+AC6+AE6 -> 5 | AE6: 1 | AF6: 0 | AH6: HL5-D | AJ6: 1 | AK6: 4 | AL6: =AI6+AK6+AM6 -> 5 | AM6: 1 | AN6: 0 | AP6: HL5-D | AR6: 13 | AS6: 14 | AT6: =AQ6+AS6+AU6 -> 14 | AU6: 0 | AV6: 0
R7: HL5-G | S7: 5 | T7: 15 | U7: 17 | V7: =S7+U7+W7 -> 22 | W7: 0 | X7: 1 | Z7: HL5-G | AA7: 1 | AB7: 19 | AC7: 19 | AD7: =AA7+AC7+AE7 -> 34 | AE7: 14 | AF7: 1 | AH7: HL5-G | AI7: 1 | AJ7: 21 | AK7: 27 | AL7: =AI7+AK7+AM7 -> 33 | AM7: 5 | AN7: 0 | AP7: HL5-G | AR7: 68 | AS7: 68 | AT7: =AQ7+AS7+AU7 -> 68 | AU7: 0 | AV7: 0
R8: TOTAL | S8: =SUM(S5:S7) -> 8 | T8: =SUM(T5:T7) -> 18 | U8: =SUM(U5:U7) -> 23 | V8: =S8+U8+W8 -> 32 | W8: =SUM(W5:W7) -> 1 | X8: =SUM(X5:X7) -> 1 | Z8: TOTAL | AA8: =SUM(AA5:AA7) -> 3 | AB8: =SUM(AB5:AB7) -> 20 | AC8: =SUM(AC5:AC7) -> 23 | AD8: =AA8+AC8+AE8 -> 41 | AE8: =SUM(AE5:AE7) -> 15 | AF8: =SUM(AF5:AF7) -> 1 | AH8: TOTAL | AI8: =SUM(AI5:AI7) -> 2 | AJ8: =SUM(AJ5:AJ7) -> 22 | AK8: =SUM(AK5:AK7) -> 31 | AL8: =AI8+AK8+AM8 -> 39 | AM8: =SUM(AM5:AM7) -> 6 | AN8: =SUM(AN5:AN7) -> 0 | AP8: TOTAL | AQ8: =SUM(AQ5:AQ7) -> 1 | AR8: =SUM(AR5:AR7) -> 84 | AS8: =SUM(AS5:AS7) -> 85 | AT8: =AQ8+AS8+AU8 -> 86 | AU8: =SUM(AU5:AU7) -> 0 | AV8: =SUM(AV5:AV7) -> 0
S9: =(S8+W8)/V8 -> 0.28125 | AA9: =(AA8+AE8)/AD8 -> 0.43902439 | AI9: =(AI8+AM8)/AL8 -> 0.20512821 | AQ9: =(AQ8+AU8)/AT8 -> 0.011627907
L11: PRAZO ATIVAÇÃO | M11: (Vários itens)
F13: CONSTRUÇÃO | G13: QTD SITES | I13: ATIVAÇÃO | J13: QTD SITES | L13: ATIVAÇÃO | M13: QTD SITES
F14: RÁDIO | G14: 9 | I14: ATIVO | J14: 1 | L14: ATIVO | M14: 1
F15: REDE OK | G15: 5 | I15: NA | J15: 3 | L15: Total Geral | M15: 1
F16: Total Geral | G16: 14 | I16: RÁDIO | J16: 9
I17: 46080 | J17: 1
I18: 46112 | J18: 2
I19: 46113 | J19: 2
I20: 46114 | J20: 5
I21: Total Geral | J21: 23

Sheet Planilha3
A1: ID_METRO | B1: HIERARQUIA | C1: TIPO_TRANSMISSAO | D1: TOPOLOGIA_METRO | E1: ENLACE | F1: Solução rádio ? | G1: Enlace | H1: Dist Construção B (km) | I1: Dist Formatação A (km) | J1: Observações Planejamento | K1: R$-RE TOTAL | L1: ID OBRA | M1: OBS | N1: seg 11/08/2025 11:59 - Atlas
A2: M2024EST_MGNSD_01 | B2: HL5-G | C2: FO ESTRUTURANTE | D2: MGNLV-MGNSD | E2: AVALIAR R.E e RD | F2: Sim | G2: MGNSD-MGNCC | H2: 8.9 | I2: 5.3 | J2: Canalização 3,6km | K2: 330499.87 | L2: RD015040 | M2: BUSCANDO REUSO
A3: M2024_MGPQV_01 | B3: HL5-G | C3: REUSO FO | D3: MGDVE-MGPQV | E3: AVALIAR R.E e RD | F3: Sim | G3: MGPQV-MGMAU | H3: 4.6 | I3: 24.7 | J3: Implantação 48 Postes | K3: 103895.02 | L3: RD015041 | M3: BUSCANDO REUSO
A4: M2024EST_MGPTA_01 | B4: HL5-G | C4: FO ESTRUTURANTE | D4: MGFEN-MGPTA | E4: AVALIAR R.E e RD | F4: Não | G4: Inviável sem visada para MGFEN / Região central de BH com muito prédios alto nas linhas de visada. | H4: 0.8 | I4: 1.3 | J4: Canalização MD 0,6km + 0,2 MND / Area de Sombra | K4: 162114.57 | L4: ´- | M4: PROTEÇÃO RD INVIÁVEL
A5: M2024_MGOUX | B5: HL5-G | C5: REUSO FO | D5: MGOPP-MGOUX | E5: AVALIAR R.E e RD | F5: Sim | G5: MGOUX-MGOUT | H5: 2.3 | I5: 11 | J5: Canalização 0,3km | K5: 41279.43 | L5: RD015038 | M5: BUSCANDO REUSO
A6: M2024EST_MGFIL_01 | B6: HL5-G | C6: FO ESTRUTURANTE | D6: MGCTP-MGFIL | E6: AVALIAR R.E e RD | F6: Não | G6: Inviável sem visada para MGCTP ou outros do anel / MGFIL é um poste sencilo de 15m. | H6: 9.3 | I6: 5.4 | J6: Solução Radio Estruturante | K6: - | L6: - | M6: INVIÁVEL SOLUÇÃO DE RÁDIO NO ESTRUTURANTE
A7: M2024EST_MGSMV_01 | B7: HL5-G | C7: FO ESTRUTURANTE | D7: MGEDO-MGSMV | E7: AVALIAR R.E e RD | F7: Sim | G7: MGSMV-MGEDO | H7: 6.4 | I7: 8.6 | J7: - | K7: 67205.5 | L7: RD015045 | M7: BUSCANDO REUSO
A8: M2024EST_MGUDE_01 | B8: HL5-G | C8: FO ESTRUTURANTE | D8: MGBET-MGUDE | E8: AVALIAR R.E e RD | F8: Sim | G8: MGUDE-MGBET | H8: 5.1 | I8: 10.2 | J8: Canalização 1,3 MD + 0,1 MND + Implantação 12 Postes | K8: 196316.5 | L8: RD015046 | M8: BUSCANDO REUSO
A9: M2024EST_MGNUC_01 | B9: HL5-G | C9: FO ESTRUTURANTE | D9: MGSCN-MGNUC | E9: AVALIAR R.E e RD | F9: Não | G9: Inviável / Visada apenas para MGSVC que está Flat para MGSCN | H9: 3.1 | I9: 9.6 | J9: Não existe caminho físico para proteção | K9: - | L9: - | M9: PROTEÇÃO RD INVIÁVEL

Sheet Planilha2
A1: Prior | B1: MUNICIPIO | C1: HIERARQUIA | D1: SITE | E1: Topologia | F1: alvará | G1: ID | H1: status | I1: X | J1: OO
A2: 1 | B2: Uberlândia | C2: HL4 | D2: MGUSO | E2: MGUTP-MGUSO-MGUTP | F2: ok | G2: 565290 | H2: SIM CANALIZAR | I2: =_xlfn.XLOOKUP(G:G,'Estruturante Móvel'!AB:AB,'Estruturante Móvel'!E:E,1,0) -> REDE OK
A3: 1 | B3: Uberlândia | C3: HL4 | D3: MGUBR | E3: MGUTP-MGUBR-MGUTP | F3: ok | G3: 565291 | H3: SIM CANALIZAR | I3: =_xlfn.XLOOKUP(G:G,'Estruturante Móvel'!AB:AB,'Estruturante Móvel'!E:E,1,0) -> REDE OK
A4: 1 | B4: Uberlândia | C4: HL4 | D4: MGCJN | E4: MGUTP-MGCJN-MGUTP | F4: ok | G4: 565294 | H4: SIM CANALIZAR | I4: =_xlfn.XLOOKUP(G:G,'Estruturante Móvel'!AB:AB,'Estruturante Móvel'!E:E,1,0) -> REDE OK
A5: 2 | B5: Uberlândia | C5: HL5D | D5: MGUNM | E5: MGCJN-MGUNM-MGCJN | F5: ok | G5: 564924 | H5: REDE OK | I5: =_xlfn.XLOOKUP(G:G,'Estruturante Móvel'!AB:AB,'Estruturante Móvel'!E:E,1,0) -> REDE OK
A6: 2 | B6: Uberlândia | C6: HL5D | D6: MGUMS | E6: MGCJN-MGUMS-MGCJN | F6: ok | G6: 566382 | H6: SIM CANALIZAR | I6: =_xlfn.XLOOKUP(G:G,'Estruturante Móvel'!AB:AB,'Estruturante Móvel'!E:E,1,0) -> 1
A7: 2 | B7: Uberlândia | C7: HL5D | D7: MGCIN | E7: MGUBR-MGCIN-MGUBR | F7: ok | G7: 566321 | H7: REDE OK | I7: =_xlfn.XLOOKUP(G:G,'Estruturante Móvel'!AB:AB,'Estruturante Móvel'!E:E,1,0) -> REDE OK
A8: 2 | B8: Uberlândia | C8: HL5D | D8: MGGML | E8: MGUBR-MGGML-MGUBR | F8: ok | G8: 566278 | H8: REDE OK | I8: =_xlfn.XLOOKUP(G:G,'Estruturante Móvel'!AB:AB,'Estruturante Móvel'!E:E,1,0) -> 1
A9: 2 | B9: Uberlândia | C9: HL5D | D9: MGUAC | E9: MGUBR-MGUAC-MGUBR | F9: ok | G9: 566322 | H9: SIM CANALIZAR | I9: =_xlfn.XLOOKUP(G:G,'Estruturante Móvel'!AB:AB,'Estruturante Móvel'!E:E,1,0) -> 1
A10: 2 | B10: Uberlândia | C10: HL5D | D10: MGUMH | E10: MGUBR-MGUMH-MGUBR | F10: ok | G10: 566317 | H10: REDE OK | I10: =_xlfn.XLOOKUP(G:G,'Estruturante Móvel'!AB:AB,'Estruturante Móvel'!E:E,1,0) -> REDE OK
A11: 2 | B11: Uberlândia | C11: HL5D | D11: MGUPB | E11: MGUBR-MGUPB-MGUBR | F11: não | G11: 566324 | H11: REDE OK | I11: =_xlfn.XLOOKUP(G:G,'Estruturante Móvel'!AB:AB,'Estruturante Móvel'!E:E,1,0) -> REDE OK
A12: 2 | B12: Uberlândia | C12: HL5D | D12: MGAVN | E12: MGUSO-MGAVN-MGUSO | F12: ok | G12: 566327 | H12: SIM CANALIZAR | I12: =_xlfn.XLOOKUP(G:G,'Estruturante Móvel'!AB:AB,'Estruturante Móvel'!E:E,1,0) -> 1
A13: 2 | B13: Uberlândia | C13: HL5D | D13: MGGDN | E13: MGUSO-MGGDN-MGUSO | F13: ok | G13: 566300 | H13: SIM CANALIZAR | I13: =_xlfn.XLOOKUP(G:G,'Estruturante Móvel'!AB:AB,'Estruturante Móvel'!E:E,1,0) -> 1
... A17: 2 | B17: Uberlândia | C17: HL5D | D17: MGUFU | E17: MGUTP-MGUFU-MGUTP/MGUTP | F17: ok | G17: 566399 | H17: SIM CANALIZAR | I17: =_xlfn.XLOOKUP(G:G,'Estruturante Móvel'!AB:AB,'Estruturante Móvel'!E:E,1,0) -> 1
A18: 3 | B18: Uberlândia | C18: HL5G | D18: MGUJR | E18: MGCJN-MGUJR-MGCJN | G18: NA | H18: ATENDIMENTO RADIO | I18: =_xlfn.XLOOKUP(G:G,'Estruturante Móvel'!AB:AB,'Estruturante Móvel'!E:E,1,0) -> RÁDIO | J18: X
A19: 3 | B19: Uberlândia | C19: HL5G | D19: MGUTB | E19: MGCJN-MGUTB-MGCJN | G19: 565323 | H19: REDE OK | I19: =_xlfn.XLOOKUP(G:G,'Estruturante Móvel'!AB:AB,'Estruturante Móvel'!E:E,1,0) -> 1 | J19: X
A20: 3 | B20: Uberlândia | C20: HL5G | D20: MGPLN | E20: MGCJN-MGPLN-MGCJN | F20: SIM | G20: 566366 | H20: SIM CANALIZAR | I20: =_xlfn.XLOOKUP(G:G,'Estruturante Móvel'!AB:AB,'Estruturante Móvel'!E:E,1,0) -> REDE OK | J20: X
A21: 3 | B21: Uberlândia | C21: HL5G | D21: MGUVU | E21: MGCJN-MGUVU-MGCJN | F21: SIM | G21: 566372 | H21: SIM CANALIZAR | I21: =_xlfn.XLOOKUP(G:G,'Estruturante Móvel'!AB:AB,'Estruturante Móvel'!E:E,1,0) -> 1 | J21: X
A22: 3 | B22: Uberlândia | C22: HL5G | D22: MGUPN | E22: MGUMS-MGUPN-MGUMS | G22: 566400 | H22: NÃO TEM CANALIZAÇÃO NO DRAFT | I22: =_xlfn.XLOOKUP(G:G,'Estruturante Móvel'!AB:AB,'Estruturante Móvel'!E:E,1,0) -> REDE OK | J22: X
A23: 3 | B23: Uberlândia | C23: HL5G | D23: MGUJC | E23: MGCJN-MGUJC-MGCJN | G23: 565333 | H23: REDE OK | I23: =_xlfn.XLOOKUP(G:G,'Estruturante Móvel'!AB:AB,'Estruturante Móvel'!E:E,1,0) -> REDE OK | J23: X
A24: 3 | B24: Uberlândia | C24: HL5G | D24: MGTCN | E24: MGLUN-MGTCN-MGLUN | G24: 566402 | H24: NÃO TEM CANALIZAÇÃO NO DRAFT | I24: =_xlfn.XLOOKUP(G:G,'Estruturante Móvel'!AB:AB,'Estruturante Móvel'!E:E,1,0) -> REDE OK | J24: X
A25: 3 | B25: Uberlândia | C25: HL5G | D25: MGUVM | E25: MGCIN-MGUVM-MGCIN | G25: 566320 | H25: REDE OK | I25: =_xlfn.XLOOKUP(G:G,'Estruturante Móvel'!AB:AB,'Estruturante Móvel'!E:E,1,0) -> REDE OK | J25: X
A26: 3 | B26: Uberlândia | C26: HL5G | D26: MGSCZ | E26: MGCIN-MGSCZ-MGCIN | G26: 566283 | H26: NÃO TEM CANALIZAÇÃO NO DRAFT | I26: =_xlfn.XLOOKUP(G:G,'Estruturante Móvel'!AB:AB,'Estruturante Móvel'!E:E,1,0) -> REDE OK | J26: X
A27: 3 | B27: Uberlândia | C27: HL5G | D27: MGOSC | E27: MGUBR-MGOSC-MGURB | G27: 565348 | H27: NÃO TEM CANALIZAÇÃO NO DRAFT | I27: =_xlfn.XLOOKUP(G:G,'Estruturante Móvel'!AB:AB,'Estruturante Móvel'!E:E,1,0) -> REDE OK | J27: X
A28: 3 | B28: Uberlândia | C28: HL5G | D28: MGUPD | E28: MGUBR-MGUPD-MGUBR | G28: NA | H28: CANCELADO | I28: =_xlfn.XLOOKUP(G:G,'Estruturante Móvel'!AB:AB,'Estruturante Móvel'!E:E,1,0) -> RÁDIO | J28: X
A29: 3 | B29: Uberlândia | C29: HL5G | D29: MGULZ | E29: MGUBR-MGULZ-MGUBR | G29: 566306 | H29: REDE OK | I29: =_xlfn.XLOOKUP(G:G,'Estruturante Móvel'!AB:AB,'Estruturante Móvel'!E:E,1,0) -> 1 | J29: X
A30: 3 | B30: Uberlândia | C30: HL5G | D30: MGCLN | E30: MGUBR-MGCLN-MGUBR | G30: 566274 | H30: NÃO TEM CANALIZAÇÃO NO DRAFT | I30: =_xlfn.XLOOKUP(G:G,'Estruturante Móvel'!AB:AB,'Estruturante Móvel'!E:E,1,0) -> REDE OK | J30: X
A31: 3 | B31: Uberlândia | C31: HL5G | D31: MGUMU | E31: MGUAC-MGUMU-MGUAC | G31: 566290 | H31: REDE OK | I31: =_xlfn.XLOOKUP(G:G,'Estruturante Móvel'!AB:AB,'Estruturante Móvel'!E:E,1,0) -> REDE OK | J31: X
A32: 3 | B32: Uberlândia | C32: HL5G | D32: MGBRN | E32: MGUBR-MGBRN-MGUBR | G32: 523454 | H32: SIM CANALIZAR | I32: =_xlfn.XLOOKUP(G:G,'Estruturante Móvel'!AB:AB,'Estruturante Móvel'!E:E,1,0) -> REDE OK | J32: X
A33: 3 | B33: Uberlândia | C33: HL5G | D33: MGSHN | E33: MGTYN-MGSHN-MGTYN | G33: 566311 | H33: REDE OK | I33: =_xlfn.XLOOKUP(G:G,'Estruturante Móvel'!AB:AB,'Estruturante Móvel'!E:E,1,0) -> 1 | J33: X
A34: 3 | B34: Uberlândia | C34: HL5G | D34: MGCGB | E34: MGGML-MGCGB-MGGML | G34: 566285 | H34: SIM CANALIZAR | I34: =_xlfn.XLOOKUP(G:G,'Estruturante Móvel'!AB:AB,'Estruturante Móvel'!E:E,1,0) -> 1 | J34: X
A35: 3 | B35: Uberlândia | C35: HL5G | D35: MGUXJ | E35: MGGDN-MGUXJ-MGGDN | G35: 564952 | H35: REDE OK | I35: =_xlfn.XLOOKUP(G:G,'Estruturante Móvel'!AB:AB,'Estruturante Móvel'!E:E,1,0) -> REDE OK | J35: X
A36: 3 | B36: Uberlândia | C36: HL5G | D36: MGUDA | E36: MGAVN-MGUDA-MGAVN | G36: 565359 | H36: REDE OK | I36: =_xlfn.XLOOKUP(G:G,'Estruturante Móvel'!AB:AB,'Estruturante Móvel'!E:E,1,0) -> REDE OK | J36: X
A37: 3 | B37: Uberlândia | C37: HL5G | D37: MGUMO | E37: MGAVN-MGUMO-MGAVN | G37: 565363 | H37: REDE OK | I37: =_xlfn.XLOOKUP(G:G,'Estruturante Móvel'!AB:AB,'Estruturante Móvel'!E:E,1,0) -> REDE OK | J37: X
A38: 3 | B38: Uberlândia | C38: HL5G | D38: MGRAL | E38: MGAVN-MGRAL-MGAVN | G38: 566270 | H38: REDE OK | I38: =_xlfn.XLOOKUP(G:G,'Estruturante Móvel'!AB:AB,'Estruturante Móvel'!E:E,1,0) -> REDE OK | J38: X
A39: 3 | B39: Uberlândia | C39: HL5G | D39: MGRBN | E39: MGUTP-MGRBN-MGUTP | G39: 566384 | H39: SIM CANALIZAR | I39: =_xlfn.XLOOKUP(G:G,'Estruturante Móvel'!AB:AB,'Estruturante Móvel'!E:E,1,0) -> REDE OK | J39: X
A40: 3 | B40: Uberlândia | C40: HL5G | D40: MGUSA | E40: MGUTP-MGUSA-MGUTP | G40: 566395 | H40: NÃO TEM CANALIZAÇÃO NO DRAFT | I40: =_xlfn.XLOOKUP(G:G,'Estruturante Móvel'!AB:AB,'Estruturante Móvel'!E:E,1,0) -> REDE OK | J40: X
... A43: 3 | B43: Uberlândia | C43: HL5G | D43: MGLDN | E43: MGUTP-MGLDN-MGUTP | G43: 566388 | H43: NÃO TEM CANALIZAÇÃO NO DRAFT | I43: =_xlfn.XLOOKUP(G:G,'Estruturante Móvel'!AB:AB,'Estruturante Móvel'!E:E,1,0) -> CANCELADO | J43: X
A44: 3 | B44: Uberlândia | C44: HL5G | D44: MGULA | E44: MGUTP-MGULA-MGUTP | F44: SIM | G44: 566377 | H44: SIM CANALIZAR | I44: =_xlfn.XLOOKUP(G:G,'Estruturante Móvel'!AB:AB,'Estruturante Móvel'!E:E,1,0) -> REDE OK | J44: X
A45: 3 | B45: Uberlândia | C45: HL5G | D45: MGUBM | E45: MGUTP-MGUBM-MGTBN-MGUTP | F45: SIM | G45: 566390 | H45: SIM CANALIZAR | I45: =_xlfn.XLOOKUP(G:G,'Estruturante Móvel'!AB:AB,'Estruturante Móvel'!E:E,1,0) -> REDE OK | J45: X
...

Sheet lic_28.05
A1: ID_METRO | B1: LOCAL
A2: M2024EST_MGAES_01 | B2: =VLOOKUP(A2,'Estruturante Móvel'!B:Q,16,0) -> BELO HORIZONTE
A3: M2024EST_MGAPS_01 | B3: =VLOOKUP(A3,'Estruturante Móvel'!B:Q,16,0) -> BELO HORIZONTE
A4: M2024EST_MGBGO_01 | B4: =VLOOKUP(A4,'Estruturante Móvel'!B:Q,16,0) -> BELO HORIZONTE
A5: M2024EST_MGBTM_01 | B5: =VLOOKUP(A5,'Estruturante Móvel'!B:Q,16,0) -> BELO HORIZONTE
A6: M2024EST_MGCUC_01 | B6: =VLOOKUP(A6,'Estruturante Móvel'!B:Q,16,0) -> BELO HORIZONTE
A7: M2024EST_MGHGA_01 | B7: =VLOOKUP(A7,'Estruturante Móvel'!B:Q,16,0) -> BELO HORIZONTE
A8: M2025EST_MGSML_01 | B8: =VLOOKUP(A8,'Estruturante Móvel'!B:Q,16,0) -> SETE LAGOAS_2025
A9: M2025EST_MGSLN_01 | B9: =VLOOKUP(A9,'Estruturante Móvel'!B:Q,16,0) -> SETE LAGOAS_2025
A10: M2025EST_MGARN_01 | B10: =VLOOKUP(A10,'Estruturante Móvel'!B:Q,16,0) -> UBERABA_2025
A11: M2025EST_MGGBV_01 | B11: =VLOOKUP(A11,'Estruturante Móvel'!B:Q,16,0) -> GOVERNADOR VALADARES_2025
A12: M2025EST_MGVBT_01 | B12: =VLOOKUP(A12,'Estruturante Móvel'!B:Q,16,0) -> GOVERNADOR VALADARES_2025
A13: M2025EST_MGGDI_01 | B13: =VLOOKUP(A13,'Estruturante Móvel'!B:Q,16,0) -> GOVERNADOR VALADARES_2025
... A94: M2025EST_MGTCN_01 | B94: =VLOOKUP(A94,'Estruturante Móvel'!B:Q,16,0) -> UBERLÂNDIA_2025

Sheet CRONOGRAMA_CONST+MIGRACAO
B2: Visão Geral - Estruturante MG [ ENTREGA FIBRA ] | L2: =WEEKNUM(L4) -> 36 | M2: =WEEKNUM(L4) -> 36 | N2: =WEEKNUM(N4) -> 36 | O2: =WEEKNUM(N4) -> 36 | P2: =WEEKNUM(P4) -> 36 | Q2: =WEEKNUM(P4) -> 36 | R2: =WEEKNUM(R4) -> 36 | S2: =WEEKNUM(R4) -> 36 | T2: =WEEKNUM(T4) -> 36 | U2: =WEEKNUM(T4) -> 36 | V2: =WEEKNUM(V4) -> 36 | W2: =WEEKNUM(V4) -> 36 | X2: =WEEKNUM(X4) -> 36 | Y2: =WEEKNUM(X4) -> 36 | Z2: =WEEKNUM(Z4) -> 37 | AA2: =WEEKNUM(Z4) -> 37 | AB2: =WEEKNUM(AB4) -> 37 | AC2: =WEEKNUM(AB4) -> 37 | AD2: =WEEKNUM(AD4) -> 37 | AE2: =WEEKNUM(AD4) -> 37 | AF2: =WEEKNUM(AF4) -> 37 | AG2: =WEEKNUM(AF4) -> 37 | AH2: =WEEKNUM(AH4) -> 37 | AI2: =WEEKNUM(AH4) -> 37 | AJ2: =WEEKNUM(AJ4) -> 37 | AK2: =WEEKNUM(AJ4) -> 37 | AL2: =WEEKNUM(AL4) -> 37 | AM2: =WEEKNUM(AL4) -> 37 | AN2: =WEEKNUM(AN4) -> 38 | AO2: =WEEKNUM(AN4) -> 38 | AP2: =WEEKNUM(AP4) -> 38 | AQ2: =WEEKNUM(AP4) -> 38 | AR2: =WEEKNUM(AR4) -> 38 | AS2: =WEEKNUM(AR4) -> 38 | AT2: =WEEKNUM(AT4) -> 38 | AU2: =WEEKNUM(AT4) -> 38 | AV2: =WEEKNUM(AV4) -> 38 | AW2: =WEEKNUM(AV4) -> 38 | AX2: =WEEKNUM(AX4) -> 38 | AY2: =WEEKNUM(AX4) -> 38 | AZ2: =WEEKNUM(AZ4) -> 38 | BA2: =WEEKNUM(AZ4) -> 38 | BB2: =WEEKNUM(BB4) -> 39 | BC2: =WEEKNUM(BB4) -> 39 | BD2: =WEEKNUM(BD4) -> 39 | BE2: =WEEKNUM(BD4) -> 39 | BF2: =WEEKNUM(BF4) -> 39 | BG2: =WEEKNUM(BF4) -> 39 | BH2: =WEEKNUM(BH4) -> 39 | BI2: =WEEKNUM(BH4) -> 39 | BJ2: =WEEKNUM(BJ4) -> 39 | BK2: =WEEKNUM(BJ4) -> 39 | BL2: =WEEKNUM(BL4) -> 39 | BM2: =WEEKNUM(BL4) -> 39 | BN2: =WEEKNUM(BN4) -> 39 | BO2: =WEEKNUM(BN4) -> 39 | BP2: =WEEKNUM(BP4) -> 40 | BQ2: =WEEKNUM(BP4) -> 40 | BR2: =WEEKNUM(BR4) -> 40 | BS2: =WEEKNUM(BR4) -> 40 | BT2: =WEEKNUM(BT4) -> 40 | BU2: =WEEKNUM(BT4) -> 40 | BV2: =WEEKNUM(BV4) -> 40 | BW2: =WEEKNUM(BV4) -> 40 | BX2: =WEEKNUM(BX4) -> 40 | BY2: =WEEKNUM(BX4) -> 40 | BZ2: =WEEKNUM(BZ4) -> 40 | CA2: =WEEKNUM(BZ4) -> 40 | CB2: =WEEKNUM(CB4) -> 40 | CC2: =WEEKNUM(CB4) -> 40 | CD2: =WEEKNUM(CD4) -> 41 | CE2: =WEEKNUM(CD4) -> 41 | CF2: =WEEKNUM(CF4) -> 41 | CG2: =WEEKNUM(CF4) -> 41 | CH2: =WEEKNUM(CH4) -> 41 | CI2: =WEEKNUM(CH4) -> 41 | CJ2: =WEEKNUM(CJ4) -> 41 | CK2: =WEEKNUM(CJ4) -> 41 | CL2: =WEEKNUM(CL4) -> 41 | CM2: =WEEKNUM(CL4) -> 41 | CN2: =WEEKNUM(CN4) -> 41 | CO2: =WEEKNUM(CN4) -> 41 | CP2: =WEEKNUM(CP4) -> 41 | CQ2: =WEEKNUM(CP4) -> 41 | CR2: =WEEKNUM(CR4) -> 42 | CS2: =WEEKNUM(CR4) -> 42 | CT2: =WEEKNUM(CT4) -> 42 | CU2: =WEEKNUM(CT4) -> 42 | CV2: =WEEKNUM(CV4) -> 42 | CW2: =WEEKNUM(CV4) -> 42 | CX2: =WEEKNUM(CX4) -> 42 | CY2: =WEEKNUM(CX4) -> 42 | CZ2: =WEEKNUM(CZ4) -> 42 | DA2: =WEEKNUM(CZ4) -> 42 | DB2: =WEEKNUM(DB4) -> 42 | DC2: =WEEKNUM(DB4) -> 42 | DD2: =WEEKNUM(DD4) -> 42 | DE2: =WEEKNUM(DD4) -> 42 | DF2: =WEEKNUM(DF4) -> 43 | DG2: =WEEKNUM(DF4) -> 43 | DH2: =WEEKNUM(DH4) -> 43 | DI2: =WEEKNUM(DH4) -> 43 | DJ2: =WEEKNUM(DJ4) -> 43 | DK2: =WEEKNUM(DJ4) -> 43 | DL2: =WEEKNUM(DL4) -> 43 | DM2: =WEEKNUM(DL4) -> 43 | DN2: =WEEKNUM(DN4) -> 43 | DO2: =WEEKNUM(DN4) -> 43 | DP2: =WEEKNUM(DP4) -> 43 | DQ2: =WEEKNUM(DP4) -> 43 | DR2: =WEEKNUM(DR4) -> 43 | DS2: =WEEKNUM(DR4) -> 43 | DT2: =WEEKNUM(DT4) -> 44 | DU2: =WEEKNUM(DT4) -> 44 | DV2: =WEEKNUM(DV4) -> 44 | DW2: =WEEKNUM(DV4) -> 44 | DX2: =WEEKNUM(DX4) -> 44 | DY2: =WEEKNUM(DX4) -> 44 | DZ2: =WEEKNUM(DZ4) -> 44 | EA2: =WEEKNUM(DZ4) -> 44 | EB2: =WEEKNUM(EB4) -> 44 | EC2: =WEEKNUM(EB4) -> 44 | ED2: =WEEKNUM(ED4) -> 44 | EE2: =WEEKNUM(ED4) -> 44 | EF2: =WEEKNUM(EF4) -> 44 | EG2: =WEEKNUM(EF4) -> 44 | EH2: =WEEKNUM(EH4) -> 45 | EI2: =WEEKNUM(EH4) -> 45 | EJ2: =WEEKNUM(EJ4) -> 45 | EK2: =WEEKNUM(EJ4) -> 45 | EL2: =WEEKNUM(EL4) -> 45 | EM2: =WEEKNUM(EL4) -> 45 | EN2: =WEEKNUM(EN4) -> 45 | EO2: =WEEKNUM(EN4) -> 45 | EP2: =WEEKNUM(EP4) -> 45 | EQ2: =WEEKNUM(EP4) -> 45 | ER2: =WEEKNUM(ER4) -> 45 | ES2: =WEEKNUM(ER4) -> 45 | ET2: =WEEKNUM(ET4) -> 45 | EU2: =WEEKNUM(ET4) -> 45 | EV2: =WEEKNUM(EV4) -> 46 | EW2: =WEEKNUM(EV4) -> 46 | EX2: =WEEKNUM(EX4) -> 46 | EY2: =WEEKNUM(EX4) -> 46 | EZ2: =WEEKNUM(EZ4) -> 46 | FA2: =WEEKNUM(EZ4) -> 46 | FB2: =WEEKNUM(FB4) -> 46 | FC2: =WEEKNUM(FB4) -> 46 | FD2: =WEEKNUM(FD4) -> 46 | FE2: =WEEKNUM(FD4) -> 46 | FF2: =WEEKNUM(FF4) -> 46 | FG2: =WEEKNUM(FF4) -> 46 | FH2: =WEEKNUM(FH4) -> 46 | FI2: =WEEKNUM(FH4) -> 46 | FJ2: =WEEKNUM(FJ4) -> 47 | FK2: =WEEKNUM(FJ4) -> 47 | FL2: =WEEKNUM(FL4) -> 47 | FM2: =WEEKNUM(FL4) -> 47 | FN2: =WEEKNUM(FN4) -> 47 | FO2: =WEEKNUM(FN4) -> 47 | FP2: =WEEKNUM(FP4) -> 47 | FQ2: =WEEKNUM(FP4) -> 47 | FR2: =WEEKNUM(FR4) -> 47 | FS2: =WEEKNUM(FR4) -> 47 | FT2: =WEEKNUM(FT4) -> 47 | FU2: =WEEKNUM(FT4) -> 47 | FV2: =WEEKNUM(FV4) -> 47 | FW2: =WEEKNUM(FV4) -> 47 | FX2: =WEEKNUM(FX4) -> 48 | FY2: =WEEKNUM(FX4) -> 48 | FZ2: =WEEKNUM(FZ4) -> 48 | GA2: =WEEKNUM(FZ4) -> 48 | GB2: =WEEKNUM(GB4) -> 48 | GC2: =WEEKNUM(GB4) -> 48 | GD2: =WEEKNUM(GD4) -> 48 | GE2: =WEEKNUM(GD4) -> 48 | GF2: =WEEKNUM(GF4) -> 48 | GG2: =WEEKNUM(GF4) -> 48 | GH2: =WEEKNUM(GH4) -> 48 | GI2: =WEEKNUM(GH4) -> 48 | GJ2: =WEEKNUM(GJ4) -> 48 | GK2: =WEEKNUM(GJ4) -> 48 | GL2: =WEEKNUM(GL4) -> 49 | GM2: =WEEKNUM(GL4) -> 49 | GN2: =WEEKNUM(GN4) -> 49 | GO2: =WEEKNUM(GN4) -> 49 | GP2: =WEEKNUM(GP4) -> 49 | GQ2: =WEEKNUM(GP4) -> 49 | GR2: =WEEKNUM(GR4) -> 49 | GS2: =WEEKNUM(GR4) -> 49 | GT2: =WEEKNUM(GT4) -> 49 | GU2: =WEEKNUM(GT4) -> 49 | GV2: =WEEKNUM(GV4) -> 49 | GW2: =WEEKNUM(GV4) -> 49 | GX2: =WEEKNUM(GX4) -> 49 | GY2: =WEEKNUM(GX4) -> 49 | GZ2: =WEEKNUM(GZ4) -> 50 | HA2: =WEEKNUM(GZ4) -> 50 | HB2: =WEEKNUM(HB4) -> 50 | HC2: =WEEKNUM(HB4) -> 50 | HD2: =WEEKNUM(HD4) -> 50 | HE2: =WEEKNUM(HD4) -> 50 | HF2: =WEEKNUM(HF4) -> 50 | HG2: =WEEKNUM(HF4) -> 50 | HH2: =WEEKNUM(HH4) -> 50 | HI2: =WEEKNUM(HH4) -> 50 | HJ2: =WEEKNUM(HJ4) -> 50 | HK2: =WEEKNUM(HJ4) -> 50 | HL2: =WEEKNUM(HL4) -> 50 | HM2: =WEEKNUM(HL4) -> 50 | HN2: =WEEKNUM(HN4) -> 51 | HO2: =WEEKNUM(HN4) -> 51 | HP2: =WEEKNUM(HP4) -> 51 | HQ2: =WEEKNUM(HP4) -> 51 | HR2: =WEEKNUM(HR4) -> 51 | HS2: =WEEKNUM(HR4) -> 51 | HT2: =WEEKNUM(HT4) -> 51 | HU2: =WEEKNUM(HT4) -> 51 | HV2: =WEEKNUM(HV4) -> 51 | HW2: =WEEKNUM(HV4) -> 51 | HX2: =WEEKNUM(HX4) -> 51 | HY2: =WEEKNUM(HX4) -> 51 | HZ2: =WEEKNUM(HZ4) -> 51 | IA2: =WEEKNUM(HZ4) -> 51 | IB2: =WEEKNUM(IB4) -> 52 | IC2: =WEEKNUM(IB4) -> 52 | ID2: =WEEKNUM(ID4) -> 52 | IE2: =WEEKNUM(ID4) -> 52 | IF2: =WEEKNUM(IF4) -> 52 | IG2: =WEEKNUM(IF4) -> 52 | IH2: =WEEKNUM(IH4) -> 52 | II2: =WEEKNUM(IH4) -> 52 | IJ2: =WEEKNUM(IJ4) -> 52 | IK2: =WEEKNUM(IJ4) -> 52 | IL2: =WEEKNUM(IL4) -> 52 | IM2: =WEEKNUM(IL4) -> 52 | IN2: =WEEKNUM(IN4) -> 52 | IO2: =WEEKNUM(IN4) -> 52 | IP2: =WEEKNUM(IP4) -> 53 | IQ2: =WEEKNUM(IP4) -> 53 | IR2: =WEEKNUM(IR4) -> 53 | IS2: =WEEKNUM(IR4) -> 53 | IT2: =WEEKNUM(IT4) -> 53 | IU2: =WEEKNUM(IT4) -> 53 | IV2: =WEEKNUM(IV4) -> 1 | IW2: =WEEKNUM(IV4) -> 1 | IX2: =WEEKNUM(IX4) -> 1 | IY2: =WEEKNUM(IX4) -> 1 | IZ2: =WEEKNUM(IZ4) -> 1 | JA2: =WEEKNUM(IZ4) -> 1 | JB2: =WEEKNUM(JB4) -> 1 | JC2: =WEEKNUM(JB4) -> 1 | JD2: =WEEKNUM(JD4) -> 2 | JE2: =WEEKNUM(JD4) -> 2 | JF2: =WEEKNUM(JF4) -> 2 | JG2: =WEEKNUM(JF4) -> 2 | JH2: =WEEKNUM(JH4) -> 2 | JI2: =WEEKNUM(JH4) -> 2 | JJ2: =WEEKNUM(JJ4) -> 2 | JK2: =WEEKNUM(JJ4) -> 2 | JL2: =WEEKNUM(JL4) -> 2 | JM2: =WEEKNUM(JL4) -> 2 | JN2: =WEEKNUM(JN4) -> 2 | JO2: =WEEKNUM(JN4) -> 2 | JP2: =WEEKNUM(JP4) -> 2 | JQ2: =WEEKNUM(JP4) -> 2 | JR2: =WEEKNUM(JR4) -> 3 | JS2: =WEEKNUM(JR4) -> 3 | JT2: =WEEKNUM(JT4) -> 3 | JU2: =WEEKNUM(JT4) -> 3 | JV2: =WEEKNUM(JV4) -> 3 | JW2: =WEEKNUM(JV4) -> 3 | JX2: =WEEKNUM(JX4) -> 3 | JY2: =WEEKNUM(JX4) -> 3 | JZ2: =WEEKNUM(JZ4) -> 3 | KA2: =WEEKNUM(JZ4) -> 3 | KB2: =WEEKNUM(KB4) -> 3 | KC2: =WEEKNUM(KB4) -> 3 | KD2: =WEEKNUM(KD4) -> 3 | KE2: =WEEKNUM(KD4) -> 3 | KF2: =WEEKNUM(KF4) -> 4 | KG2: =WEEKNUM(KF4) -> 4 | KH2: =WEEKNUM(KH4) -> 4 | KI2: =WEEKNUM(KH4) -> 4 | KJ2: =WEEKNUM(KJ4) -> 4 | KK2: =WEEKNUM(KJ4) -> 4 | KL2: =WEEKNUM(KL4) -> 4 | KM2: =WEEKNUM(KL4) -> 4 | KN2: =WEEKNUM(KN4) -> 4 | KO2: =WEEKNUM(KN4) -> 4 | KP2: =WEEKNUM(KP4) -> 4 | KQ2: =WEEKNUM(KP4) -> 4 | KR2: =WEEKNUM(KR4) -> 4 | KS2: =WEEKNUM(KR4) -> 4 | KT2: =WEEKNUM(KT4) -> 5 | KU2: =WEEKNUM(KT4) -> 5 | KV2: =WEEKNUM(KV4) -> 5 | KW2: =WEEKNUM(KV4) -> 5 | KX2: =WEEKNUM(KX4) -> 5 | KY2: =WEEKNUM(KX4) -> 5 | KZ2: =WEEKNUM(KZ4) -> 5 | LA2: =WEEKNUM(KZ4) -> 5 | LB2: =WEEKNUM(LB4) -> 5 | LC2: =WEEKNUM(LB4) -> 5 | LD2: =WEEKNUM(LD4) -> 5 | LE2: =WEEKNUM(LD4) -> 5 | LF2: =WEEKNUM(LF4) -> 5 | LG2: =WEEKNUM(LF4) -> 5 | LH2: =WEEKNUM(LH4) -> 6 | LI2: =WEEKNUM(LH4) -> 6 | LJ2: =WEEKNUM(LJ4) -> 6 | LK2: =WEEKNUM(LJ4) -> 6 | LL2: =WEEKNUM(LL4) -> 6 | LM2: =WEEKNUM(LL4) -> 6 | LN2: =WEEKNUM(LN4) -> 6 | LO2: =WEEKNUM(LN4) -> 6 | LP2: =WEEKNUM(LP4) -> 6 | LQ2: =WEEKNUM(LP4) -> 6 | LR2: =WEEKNUM(LR4) -> 6 | LS2: =WEEKNUM(LR4) -> 6 | LT2: =WEEKNUM(LT4) -> 6 | LU2: =WEEKNUM(LT4) -> 6 | LV2: =WEEKNUM(LV4) -> 7 | LW2: =WEEKNUM(LV4) -> 7 | LX2: =WEEKNUM(LX4) -> 7 | LY2: =WEEKNUM(LX4) -> 7 | LZ2: =WEEKNUM(LZ4) -> 7 | MA2: =WEEKNUM(LZ4) -> 7 | MB2: =WEEKNUM(MB4) -> 7 | MC2: =WEEKNUM(MB4) -> 7 | MD2: =WEEKNUM(MD4) -> 7 | ME2: =WEEKNUM(MD4) -> 7 | MF2: =WEEKNUM(MF4) -> 7 | MG2: =WEEKNUM(MF4) -> 7 | MH2: =WEEKNUM(MH4) -> 7 | MI2: =WEEKNUM(MH4) -> 7 | MJ2: =WEEKNUM(MJ4) -> 8 | MK2: =WEEKNUM(MJ4) -> 8 | ML2: =WEEKNUM(ML4) -> 8 | MM2: =WEEKNUM(ML4) -> 8 | MN2: =WEEKNUM(MN4) -> 8 | MO2: =WEEKNUM(MN4) -> 8 | MP2: =WEEKNUM(MP4) -> 8 | MQ2: =WEEKNUM(MP4) -> 8 | MR2: =WEEKNUM(MR4) -> 8 | MS2: =WEEKNUM(MR4) -> 8 | MT2: =WEEKNUM(MT4) -> 8 | MU2: =WEEKNUM(MT4) -> 8 | MV2: =WEEKNUM(MV4) -> 8 | MW2: =WEEKNUM(MV4) -> 8 | MX2: =WEEKNUM(MX4) -> 9 | MY2: =WEEKNUM(MX4) -> 9 | MZ2: =WEEKNUM(MZ4) -> 9 | NA2: =WEEKNUM(MZ4) -> 9 | NB2: =WEEKNUM(NB4) -> 9 | NC2: =WEEKNUM(NB4) -> 9 | ND2: =WEEKNUM(ND4) -> 9 | NE2: =WEEKNUM(ND4) -> 9 | NF2: =WEEKNUM(NF4) -> 9 | NG2: =WEEKNUM(NF4) -> 9 | NH2: =WEEKNUM(NH4) -> 9 | NI2: =WEEKNUM(NH4) -> 9
B3: HL4 | C3: KM | D3: QTD SITE Previsto | E3: QTD SITE Fibra OK | F3: QTD SITE Backlog | G3: EMPRESA CLASSE L | H3: FASE | I3: PREV. CONCLUSÃO | J3: EVOLUÇÃO REDE | K3: <= | L3: CRONOGRAMA DIÁRIO
K4: =TODAY() -> 46116 | L4: 45536 | N4: =L4+1 -> 45537 | P4: =N4+1 -> 45538 | R4: =P4+1 -> 45539 | T4: =R4+1 -> 45540 | V4: =T4+1 -> 45541 | X4: =V4+1 -> 45542 | Z4: =X4+1 -> 45543 | AB4: =Z4+1 -> 45544 | AD4: =AB4+1 -> 45545 | AF4: =AD4+1 -> 45546 | AH4: =AF4+1 -> 45547 | AJ4: =AH4+1 -> 45548 | AL4: =AJ4+1 -> 45549 | AN4: =AL4+1 -> 45550 | AP4: =AN4+1 -> 45551 | AR4: =AP4+1 -> 45552 | AT4: =AR4+1 -> 45553 | AV4: =AT4+1 -> 45554 | AX4: =AV4+1 -> 45555 | AZ4: =AX4+1 -> 45556 | BB4: =AZ4+1 -> 45557 | BD4: =BB4+1 -> 45558 | BF4: =BD4+1 -> 45559 | BH4: =BF4+1 -> 45560 | BJ4: =BH4+1 -> 45561 | BL4: =BJ4+1 -> 45562 | BN4: =BL4+1 -> 45563 | BP4: =BN4+1 -> 45564 | BR4: =BP4+1 -> 45565 | BT4: =BR4+1 -> 45566 | BV4: =BT4+1 -> 45567 | BX4: =BV4+1 -> 45568 | BZ4: =BX4+1 -> 45569 | CB4: =BZ4+1 -> 45570 | CD4: =CB4+1 -> 45571 | CF4: =CD4+1 -> 45572 | CH4: =CF4+1 -> 45573 | CJ4: =CH4+1 -> 45574 | CL4: =CJ4+1 -> 45575 | CN4: =CL4+1 -> 45576 | CP4: =CN4+1 -> 45577 | CR4: =CP4+1 -> 45578 | CT4: =CR4+1 -> 45579 | CV4: =CT4+1 -> 45580 | CX4: =CV4+1 -> 45581 | CZ4: =CX4+1 -> 45582 | DB4: =CZ4+1 -> 45583 | DD4: =DB4+1 -> 45584 | DF4: =DD4+1 -> 45585 | DH4: =DF4+1 -> 45586 | DJ4: =DH4+1 -> 45587 | DL4: =DJ4+1 -> 45588 | DN4: =DL4+1 -> 45589 | DP4: =DN4+1 -> 45590 | DR4: =DP4+1 -> 45591 | DT4: =DR4+1 -> 45592 | DV4: =DT4+1 -> 45593 | DX4: =DV4+1 -> 45594 | DZ4: =DX4+1 -> 45595 | EB4: =DZ4+1 -> 45596 | ED4: =EB4+1 -> 45597 | EF4: =ED4+1 -> 45598 | EH4: =EF4+1 -> 45599 | EJ4: =EH4+1 -> 45600 | EL4: =EJ4+1 -> 45601 | EN4: =EL4+1 -> 45602 | EP4: =EN4+1 -> 45603 | ER4: =EP4+1 -> 45604 | ET4: =ER4+1 -> 45605 | EV4: =ET4+1 -> 45606 | EX4: =EV4+1 -> 45607 | EZ4: =EX4+1 -> 45608 | FB4: =EZ4+1 -> 45609 | FD4: =FB4+1 -> 45610 | FF4: =FD4+1 -> 45611 | FH4: =FF4+1 -> 45612 | FJ4: =FH4+1 -> 45613 | FL4: =FJ4+1 -> 45614 | FN4: =FL4+1 -> 45615 | FP4: =FN4+1 -> 45616 | FR4: =FP4+1 -> 45617 | FT4: =FR4+1 -> 45618 | FV4: =FT4+1 -> 45619 | FX4: =FV4+1 -> 45620 | FZ4: =FX4+1 -> 45621 | GB4: =FZ4+1 -> 45622 | GD4: =GB4+1 -> 45623 | GF4: =GD4+1 -> 45624 | GH4: =GF4+1 -> 45625 | GJ4: =GH4+1 -> 45626 | GL4: =GJ4+1 -> 45627 | GN4: =GL4+1 -> 45628 | GP4: =GN4+1 -> 45629 | GR4: =GP4+1 -> 45630 | GT4: =GR4+1 -> 45631 | GV4: =GT4+1 -> 45632 | GX4: =GV4+1 -> 45633 | GZ4: =GX4+1 -> 45634 | HB4: =GZ4+1 -> 45635 | HD4: =HB4+1 -> 45636 | HF4: =HD4+1 -> 45637 | HH4: =HF4+1 -> 45638 | HJ4: =HH4+1 -> 45639 | HL4: =HJ4+1 -> 45640 | HN4: =HL4+1 -> 45641 | HP4: =HN4+1 -> 45642 | HR4: =HP4+1 -> 45643 | HT4: =HR4+1 -> 45644 | HV4: =HT4+1 -> 45645 | HX4: =HV4+1 -> 45646 | HZ4: =HX4+1 -> 45647 | IB4: =HZ4+1 -> 45648 | ID4: =IB4+1 -> 45649 | IF4: =ID4+1 -> 45650 | IH4: =IF4+1 -> 45651 | IJ4: =IH4+1 -> 45652 | IL4: =IJ4+1 -> 45653 | IN4: =IL4+1 -> 45654 | IP4: =IN4+1 -> 45655 | IR4: =IP4+1 -> 45656 | IT4: =IR4+1 -> 45657 | IV4: =IT4+1 -> 45658 | IX4: =IV4+1 -> 45659 | IZ4: =IX4+1 -> 45660 | JB4: =IZ4+1 -> 45661 | JD4: =JB4+1 -> 45662 | JF4: =JD4+1 -> 45663 | JH4: =JF4+1 -> 45664 | JJ4: =JH4+1 -> 45665 | JL4: =JJ4+1 -> 45666 | JN4: =JL4+1 -> 45667 | JP4: =JN4+1 -> 45668 | JR4: =JP4+1 -> 45669 | JT4: =JR4+1 -> 45670 | JV4: =JT4+1 -> 45671 | JX4: =JV4+1 -> 45672 | JZ4: =JX4+1 -> 45673 | KB4: =JZ4+1 -> 45674 | KD4: =KB4+1 -> 45675 | KF4: =KD4+1 -> 45676 | KH4: =KF4+1 -> 45677 | KJ4: =KH4+1 -> 45678 | KL4: =KJ4+1 -> 45679 | KN4: =KL4+1 -> 45680 | KP4: =KN4+1 -> 45681 | KR4: =KP4+1 -> 45682 | KT4: =KR4+1 -> 45683 | KV4: =KT4+1 -> 45684 | KX4: =KV4+1 -> 45685 | KZ4: =KX4+1 -> 45686 | LB4: =KZ4+1 -> 45687 | LD4: =LB4+1 -> 45688 | LF4: =LD4+1 -> 45689 | LH4: =LF4+1 -> 45690 | LJ4: =LH4+1 -> 45691 | LL4: =LJ4+1 -> 45692 | LN4: =LL4+1 -> 45693 | LP4: =LN4+1 -> 45694 | LR4: =LP4+1 -> 45695 | LT4: =LR4+1 -> 45696 | LV4: =LT4+1 -> 45697 | LX4: =LV4+1 -> 45698 | LZ4: =LX4+1 -> 45699 | MB4: =LZ4+1 -> 45700 | MD4: =MB4+1 -> 45701 | MF4: =MD4+1 -> 45702 | MH4: =MF4+1 -> 45703 | MJ4: =MH4+1 -> 45704 | ML4: =MJ4+1 -> 45705 | MN4: =ML4+1 -> 45706 | MP4: =MN4+1 -> 45707 | MR4: =MP4+1 -> 45708 | MT4: =MR4+1 -> 45709 | MV4: =MT4+1 -> 45710 | MX4: =MV4+1 -> 45711 | MZ4: =MX4+1 -> 45712 | NB4: =MZ4+1 -> 45713 | ND4: =NB4+1 -> 45714 | NF4: =ND4+1 -> 45715 | NH4: =NF4+1 -> 45716
L5: P | M5: R | N5: P | O5: R | P5: P | Q5: R | R5: P | S5: R | T5: P | U5: R | V5: P | W5: R | X5: P | Y5: R | Z5: P | AA5: R | AB5: P | AC5: R | AD5: P | AE5: R | AF5: P | AG5: R | AH5: P | AI5: R | AJ5: P | AK5: R | AL5: P | AM5: R | AN5: P | AO5: R | AP5: P | AQ5: R | AR5: P | AS5: R | AT5: P | AU5: R | AV5: P | AW5: R | AX5: P | AY5: R | AZ5: P | BA5: R | BB5: P | BC5: R | BD5: P | BE5: R | BF5: P | BG5: R | BH5: P | BI5: R | BJ5: P | BK5: R | BL5: P | BM5: R | BN5: P | BO5: R | BP5: P | BQ5: R | BR5: P | BS5: R | BT5: P | BU5: R | BV5: P | BW5: R | BX5: P | BY5: R | BZ5: P | CA5: R | CB5: P | CC5: R | CD5: P | CE5: R | CF5: P | CG5: R | CH5: P | CI5: R | CJ5: P | CK5: R | CL5: P | CM5: R | CN5: P | CO5: R | CP5: P | CQ5: R | CR5: P | CS5: R | CT5: P | CU5: R | CV5: P | CW5: R | CX5: P | CY5: R | CZ5: P | DA5: R | DB5: P | DC5: R | DD5: P | DE5: R | DF5: P | DG5: R | DH5: P | DI5: R | DJ5: P | DK5: R | DL5: P | DM5: R | DN5: P | DO5: R | DP5: P | DQ5: R | DR5: P | DS5: R | DT5: P | DU5: R | DV5: P | DW5: R | DX5: P | DY5: R | DZ5: P | EA5: R | EB5: P | EC5: R | ED5: P | EE5: R | EF5: P | EG5: R | EH5: P | EI5: R | EJ5: P | EK5: R | EL5: P | EM5: R | EN5: P | EO5: R | EP5: P | EQ5: R | ER5: P | ES5: R | ET5: P | EU5: R | EV5: P | EW5: R | EX5: P | EY5: R | EZ5: P | FA5: R | FB5: P | FC5: R | FD5: P | FE5: R | FF5: P | FG5: R | FH5: P | FI5: R | FJ5: P | FK5: R | FL5: P | FM5: R | FN5: P | FO5: R | FP5: P | FQ5: R | FR5: P | FS5: R | FT5: P | FU5: R | FV5: P | FW5: R | FX5: P | FY5: R | FZ5: P | GA5: R | GB5: P | GC5: R | GD5: P | GE5: R | GF5: P | GG5: R | GH5: P | GI5: R | GJ5: P | GK5: R | GL5: P | GM5: R | GN5: P | GO5: R | GP5: P | GQ5: R | GR5: P | GS5: R | GT5: P | GU5: R | GV5: P | GW5: R | GX5: P | GY5: R | GZ5: P | HA5: R | HB5: P | HC5: R | HD5: P | HE5: R | HF5: P | HG5: R | HH5: P | HI5: R | HJ5: P | HK5: R | HL5: P | HM5: R | HN5: P | HO5: R | HP5: P | HQ5: R | HR5: P | HS5: R | HT5: P | HU5: R | HV5: P | HW5: R | HX5: P | HY5: R | HZ5: P | IA5: R | IB5: P | IC5: R | ID5: P | IE5: R | IF5: P | IG5: R | IH5: P | II5: R | IJ5: P | IK5: R | IL5: P | IM5: R | IN5: P | IO5: R | IP5: P | IQ5: R | IR5: P | IS5: R | IT5: P | IU5: R | IV5: P | IW5: R | IX5: P | IY5: R | IZ5: P | JA5: R | JB5: P | JC5: R | JD5: P | JE5: R | JF5: P | JG5: R | JH5: P | JI5: R | JJ5: P | JK5: R | JL5: P | JM5: R | JN5: P | JO5: R | JP5: P | JQ5: R | JR5: P | JS5: R | JT5: P | JU5: R | JV5: P | JW5: R | JX5: P | JY5: R | JZ5: P | KA5: R | KB5: P | KC5: R | KD5: P | KE5: R | KF5: P | KG5: R | KH5: P | KI5: R | KJ5: P | KK5: R | KL5: P | KM5: R | KN5: P | KO5: R | KP5: P | KQ5: R | KR5: P | KS5: R | KT5: P | KU5: R | KV5: P | KW5: R | KX5: P | KY5: R | KZ5: P | LA5: R | LB5: P | LC5: R | LD5: P | LE5: R | LF5: P | LG5: R | LH5: P | LI5: R | LJ5: P | LK5: R | LL5: P | LM5: R | LN5: P | LO5: R | LP5: P | LQ5: R | LR5: P | LS5: R | LT5: P | LU5: R | LV5: P | LW5: R | LX5: P | LY5: R | LZ5: P | MA5: R | MB5: P | MC5: R | MD5: P | ME5: R | MF5: P | MG5: R | MH5: P | MI5: R | MJ5: P | MK5: R | ML5: P | MM5: R | MN5: P | MO5: R | MP5: P | MQ5: R | MR5: P | MS5: R | MT5: P | MU5: R | MV5: P | MW5: R | MX5: P | MY5: R | MZ5: P | NA5: R | NB5: P | NC5: R | ND5: P | NE5: R | NF5: P | NG5: R | NH5: P | NI5: R
